<?xml version="1.0" encoding="utf-8"?>
<!-- This URDF was automatically created by SolidWorks to URDF Exporter! Originally created by
Stephen Brawner (brawner@gmail.com) 
     Commit Version: 1.6.0-4-g7f85cfe  Build Version: 1.6.7995.38578
     For more information, please see http://wiki.ros.org/sw_urdf_exporter -->
<robot
  name="go2_description">
  <link
    name="base">
    <inertial>
      <origin
        xyz="0.021112 0 -0.005366"
        rpy="0 0 0" />
      <mass
        value="6.921" />
      <inertia
        ixx="0.02448"
        ixy="0.00012166"
        ixz="0.0014849"
        iyy="0.098077"
        iyz="-3.12E-05"
        izz="0.107" />
    </inertial>
    <visual>
      <origin
        xyz="0 0 0"
        rpy="0 0 0" />
      <geometry>
        <mesh
          filename="../dae/base.dae" />
      </geometry>
      <material
        name="">
        <color
          rgba="1 1 1 1" />
      </material>
    </visual>
    <collision>
      <origin rpy="0 0 0" xyz="0 0 0" />
      <geometry>
        <mesh
          filename="../dae/base.dae" />
        <!-- <box size="0.3762 0.0935 0.165" /> -->
      </geometry>
    </collision>
  </link>
  <link
    name="Head_upper">
    <inertial>
      <origin
        xyz="0 0 0"
        rpy="0 0 0" />
      <mass
        value="0.001" />
      <inertia
        ixx="9.6e-06"
        ixy="0"
        ixz="0"
        iyy="9.6e-06"
        iyz="0"
        izz="9.6e-06" />
    </inertial>
    <visual>
      <origin
        xyz="0 0 0"
        rpy="0 0 0" />
      <!-- <geometry>
        <cylinder radius="0.05" length="0.09" />

      </geometry> -->
      <material
        name="">
        <color
          rgba="1 1 1 1" />
      </material>
    </visual>
    <collision>
      <origin
        xyz="0 0 0"
        rpy="0 0 0" />
      <!-- <geometry>
        <cylinder radius="0.05" length="0.09" />
      </geometry> -->
    </collision>
  </link>
  <joint
    name="Head_upper_joint"
    type="fixed" dont_collapse="true">
    <origin
      xyz="0.285 0 0.01"
      rpy="0 0 0" />
    <parent
      link="base" />
    <child
      link="Head_upper" />
    <axis
      xyz="0 0 0" />
  </joint>
  <link
    name="FL_hip">
    <inertial>
      <origin
        xyz="-0.0054 0.00194 -0.000105"
        rpy="0 0 0" />
      <mass
        value="0.678" />
      <inertia
        ixx="0.00048"
        ixy="-3.01E-06"
        ixz="1.11E-06"
        iyy="0.000884"
        iyz="-1.42E-06"
        izz="0.000596" />
    </inertial>
    <visual>
      <origin rpy="0 0 0" xyz="0 0 0" />
      <geometry>
        <mesh
          filename="../dae/hip.dae" />
      </geometry>
      <material
        name="">
        <color
          rgba="1 1 1 1" />
      </material>
    </visual>
    <collision>
      <origin rpy="0 0 0" xyz="0 0.08 0" />
      <geometry>
        <box size="0.09 0.067 0.09" />
      </geometry>
    </collision>
  </link>
  <joint
    name="FL_hip_joint"
    type="revolute">
    <origin
      xyz="0.1934 0.0465 0"
      rpy="0 0 0" />
    <parent
      link="base" />
    <child
      link="FL_hip" />
    <axis
      xyz="1 0 0" />
    <limit
      lower="-1.0472"
      upper="1.0472"
      effort="23.7"
      velocity="30.1" />
  </joint>
  <link
    name="FL_thigh">
    <inertial>
      <origin
        xyz="-0.00374 -0.0223 -0.0327"
        rpy="0 0 0" />
      <mass
        value="1.152" />
      <inertia
        ixx="0.00584"
        ixy="8.72E-05"
        ixz="-0.000289"
        iyy="0.0058"
        iyz="0.000808"
        izz="0.00103" />
    </inertial>
    <visual>
      <origin
        xyz="0 0 0"
        rpy="0 0 0" />
      <geometry>
        <mesh
          filename="../dae/thigh.dae" />
      </geometry>
      <material
        name="">
        <color
          rgba="1 1 1 1" />
      </material>
    </visual>
    <collision>
      <origin rpy="0 1.5707963267948966 0" xyz="0 0 -0.1065" />
      <geometry>
        <box size="0.11 0.0245 0.034" />
      </geometry>
    </collision>
  </link>
  <joint
    name="FL_thigh_joint"
    type="revolute">
    <origin
      xyz="0 0.0955 0"
      rpy="0 0 0" />
    <parent
      link="FL_hip" />
    <child
      link="FL_thigh" />
    <axis
      xyz="0 1 0" />
    <limit
      lower="-1.5708"
      upper="3.4907"
      effort="23.7"
      velocity="30.1" />
  </joint>
  <link
    name="FL_calf">
    <inertial>
      <origin
        xyz="0.00548 -0.000975 -0.115"
        rpy="0 0 0" />
      <mass
        value="0.154" />
      <inertia
        ixx="0.00108"
        ixy="3.4E-07"
        ixz="1.72E-05"
        iyy="0.0011"
        iyz="8.28E-06"
        izz="3.29E-05" />
    </inertial>
    <visual>
      <origin
        xyz="0 0 0"
        rpy="0 0 0" />
      <geometry>
        <mesh
          filename="../dae/calf.dae" />
      </geometry>
      <material
        name="">
        <color
          rgba="1 1 1 1" />
      </material>
    </visual>
    <collision>
      <origin rpy="0 -0.21 0" xyz="0.008 0 -0.06" />
      <geometry>
        <cylinder length="0.12" radius="0.012" />
      </geometry>
    </collision>
  </link>
  <joint
    name="FL_calf_joint"
    type="revolute">
    <origin
      xyz="0 0 -0.213"
      rpy="0 0 0" />
    <parent
      link="FL_thigh" />
    <child
      link="FL_calf" />
    <axis
      xyz="0 1 0" />
    <limit
      lower="-2.7227"
      upper="-0.83776"
      effort="35.55"
      velocity="20.07" />
  </joint>
  <link
    name="FL_calflower">
    <collision>
      <origin rpy="0 0 0" xyz="0 0 0" />
      <geometry>
        <cylinder length="0.065" radius="0.011" />
      </geometry>
    </collision>
  </link>
  <joint
    name="FL_calflower_joint"
    type="fixed">
    <origin
      xyz="0.020 0 -0.148"
      rpy="0 0.05 0" />
    <parent
      link="FL_calf" />
    <child
      link="FL_calflower" />
    <axis
      xyz="0 0 0" />
  </joint>
  <link
    name="FL_calflower1">
    <collision>
      <origin rpy="0 0 0" xyz="0 0 0" />
      <geometry>
        <cylinder length="0.03" radius="0.0155" />
      </geometry>
    </collision>
  </link>
  <joint
    name="FL_calflower1_joint"
    type="fixed">
    <origin
      xyz="-0.01 0 -0.04"
      rpy="0 0.48 0" />
    <parent
      link="FL_calflower" />
    <child
      link="FL_calflower1" />
    <axis
      xyz="0 0 0" />
  </joint>
  <link
    name="FL_foot">
    <inertial>
      <origin
        xyz="0 0 0"
        rpy="0 0 0" />
      <mass
        value="0.04" />
      <inertia
        ixx="9.6e-06"
        ixy="0"
        ixz="0"
        iyy="9.6e-06"
        iyz="0"
        izz="9.6e-06" />
    </inertial>
    <visual>
      <origin
        xyz="0 0 0"
        rpy="0 0 0" />
      <geometry>
        <mesh
          filename="../dae/foot.dae" />
      </geometry>
      <material
        name="">
        <color
          rgba="1 1 1 1" />
      </material>
    </visual>
    <collision>
      <origin rpy="0 0 0" xyz="-0.002 0 0" />
      <geometry>
        <sphere radius="0.022" />
      </geometry>
    </collision>
  </link>
  <joint
    name="FL_foot_joint"
    type="fixed" dont_collapse="true">
    <origin
      xyz="0 0 -0.213"
      rpy="0 0 0" />
    <parent
      link="FL_calf" />
    <child
      link="FL_foot" />
    <axis
      xyz="0 0 0" />
  </joint>
  <link
    name="FR_hip">
    <inertial>
      <origin
        xyz="-0.0054 -0.00194 -0.000105"
        rpy="0 0 0" />
      <mass
        value="0.678" />
      <inertia
        ixx="0.00048"
        ixy="3.01E-06"
        ixz="1.11E-06"
        iyy="0.000884"
        iyz="1.42E-06"
        izz="0.000596" />
    </inertial>
    <visual>
      <origin
        xyz="0 0 0"
        rpy="3.1415 0 0" />
      <geometry>
        <mesh
          filename="../dae/hip.dae" />
      </geometry>
      <material
        name="">
        <color
          rgba="1 1 1 1" />
      </material>
    </visual>
    <collision>
      <origin rpy="0 0 0" xyz="0 -0.08 0" />
      <geometry>
        <box size="0.09 0.067 0.09" />
      </geometry>
    </collision>
  </link>
  <joint
    name="FR_hip_joint"
    type="revolute">
    <origin
      xyz="0.1934 -0.0465 0"
      rpy="0 0 0" />
    <parent
      link="base" />
    <child
      link="FR_hip" />
    <axis
      xyz="1 0 0" />
    <limit
      lower="-1.0472"
      upper="1.0472"
      effort="23.7"
      velocity="30.1" />
  </joint>
  <link
    name="FR_thigh">
    <inertial>
      <origin
        xyz="-0.00374 0.0223 -0.0327"
        rpy="0 0 0" />
      <mass
        value="1.152" />
      <inertia
        ixx="0.00584"
        ixy="-8.72E-05"
        ixz="-0.000289"
        iyy="0.0058"
        iyz="-0.000808"
        izz="0.00103" />
    </inertial>
    <visual>
      <origin
        xyz="0 0 0"
        rpy="0 0 0" />
      <geometry>
        <mesh
          filename="../dae/thigh_mirror.dae" />
      </geometry>
      <material
        name="">
        <color
          rgba="1 1 1 1" />
      </material>
    </visual>
    <collision>
      <origin rpy="0 1.5707963267948966 0" xyz="0 0 -0.1065" />
      <geometry>
        <box size="0.11 0.0245 0.034" />
      </geometry>
    </collision>
  </link>
  <joint
    name="FR_thigh_joint"
    type="revolute">
    <origin
      xyz="0 -0.0955 0"
      rpy="0 0 0" />
    <parent
      link="FR_hip" />
    <child
      link="FR_thigh" />
    <axis
      xyz="0 1 0" />
    <limit
      lower="-1.5708"
      upper="3.4907"
      effort="23.7"
      velocity="30.1" />
  </joint>
  <link
    name="FR_calf">
    <inertial>
      <origin
        xyz="0.00548 0.000975 -0.115"
        rpy="0 0 0" />
      <mass
        value="0.154" />
      <inertia
        ixx="0.00108"
        ixy="-3.4E-07"
        ixz="1.72E-05"
        iyy="0.0011"
        iyz="-8.28E-06"
        izz="3.29E-05" />
    </inertial>
    <visual>
      <origin
        xyz="0 0 0"
        rpy="0 0 0" />
      <geometry>
        <mesh
          filename="../dae/calf_mirror.dae" />
      </geometry>
      <material
        name="">
        <color
          rgba="1 1 1 1" />
      </material>
    </visual>
    <collision>
      <origin rpy="0 -0.2 0" xyz="0.01 0 -0.06" />
      <geometry>
        <cylinder length="0.12" radius="0.013" />
      </geometry>
    </collision>
  </link>
  <joint
    name="FR_calf_joint"
    type="revolute">
    <origin
      xyz="0 0 -0.213"
      rpy="0 0 0" />
    <parent
      link="FR_thigh" />
    <child
      link="FR_calf" />
    <axis
      xyz="0 1 0" />
    <limit
      lower="-2.7227"
      upper="-0.83776"
      effort="35.55"
      velocity="20.07" />
  </joint>
  <link
    name="FR_calflower">
    <collision>
      <origin rpy="0 0 0" xyz="0 0 0" />
      <geometry>
        <cylinder length="0.065" radius="0.011" />
      </geometry>
    </collision>
  </link>
  <joint
    name="FR_calflower_joint"
    type="fixed">
    <origin
      xyz="0.020 0 -0.148"
      rpy="0 0.05 0" />
    <parent
      link="FR_calf" />
    <child
      link="FR_calflower" />
    <axis
      xyz="0 0 0" />
  </joint>
  <link
    name="FR_calflower1">
    <collision>
      <origin rpy="0 0 0" xyz="0 0 0" />
      <geometry>
        <cylinder length="0.03" radius="0.0155" />
      </geometry>
    </collision>
  </link>
  <joint
    name="FR_calflower1_joint"
    type="fixed">
    <origin
      xyz="-0.01 0 -0.04"
      rpy="0 0.48 0" />
    <parent
      link="FR_calflower" />
    <child
      link="FR_calflower1" />
    <axis
      xyz="0 0 0" />
  </joint>
  <link
    name="FR_foot">
    <inertial>
      <origin
        xyz="0 0 0"
        rpy="0 0 0" />
      <mass
        value="0.04" />
      <inertia
        ixx="9.6e-06"
        ixy="0"
        ixz="0"
        iyy="9.6e-06"
        iyz="0"
        izz="9.6e-06" />
    </inertial>
    <visual>
      <origin
        xyz="0 0 0"
        rpy="0 0 0" />
      <geometry>
        <mesh
          filename="../dae/foot.dae" />
      </geometry>
      <material
        name="">
        <color
          rgba="1 1 1 1" />
      </material>
    </visual>
    <collision>
      <origin rpy="0 0 0" xyz="-0.002 0 0" />
      <geometry>
        <sphere radius="0.022" />
      </geometry>
    </collision>
  </link>
  <joint
    name="FR_foot_joint"
    type="fixed" dont_collapse="true">
    <origin
      xyz="0 0 -0.213"
      rpy="0 0 0" />
    <parent
      link="FR_calf" />
    <child
      link="FR_foot" />
    <axis
      xyz="0 0 0" />
  </joint>
  <link
    name="RL_hip">
    <inertial>
      <origin
        xyz="0.0054 0.00194 -0.000105"
        rpy="0 0 0" />
      <mass
        value="0.678" />
      <inertia
        ixx="0.00048"
        ixy="3.01E-06"
        ixz="-1.11E-06"
        iyy="0.000884"
        iyz="-1.42E-06"
        izz="0.000596" />
    </inertial>
    <visual>
      <origin
        xyz="0 0 0"
        rpy="0 3.1415 0" />
      <geometry>
        <mesh
          filename="../dae/hip.dae" />
      </geometry>
      <material
        name="">
        <color
          rgba="1 1 1 1" />
      </material>
    </visual>
    <collision>
      <origin rpy="0 0 0" xyz="0 0.08 0" />
      <geometry>
        <box size="0.09 0.067 0.09" />

      </geometry>
    </collision>
  </link>
  <joint
    name="RL_hip_joint"
    type="revolute">
    <origin
      xyz="-0.1934 0.0465 0"
      rpy="0 0 0" />
    <parent
      link="base" />
    <child
      link="RL_hip" />
    <axis
      xyz="1 0 0" />
    <limit
      lower="-1.0472"
      upper="1.0472"
      effort="23.7"
      velocity="30.1" />
  </joint>
  <link
    name="RL_thigh">
    <inertial>
      <origin
        xyz="-0.00374 -0.0223 -0.0327"
        rpy="0 0 0" />
      <mass
        value="1.152" />
      <inertia
        ixx="0.00584"
        ixy="8.72E-05"
        ixz="-0.000289"
        iyy="0.0058"
        iyz="0.000808"
        izz="0.00103" />
    </inertial>
    <visual>
      <origin
        xyz="0 0 0"
        rpy="0 0 0" />
      <geometry>
        <mesh
          filename="../dae/thigh.dae" />
      </geometry>
      <material
        name="">
        <color
          rgba="1 1 1 1" />
      </material>
    </visual>
    <collision>
      <origin rpy="0 1.5707963267948966 0" xyz="0 0 -0.1065" />
      <geometry>
        <box size="0.11 0.0245 0.034" />
      </geometry>
    </collision>
  </link>
  <joint
    name="RL_thigh_joint"
    type="revolute">
    <origin
      xyz="0 0.0955 0"
      rpy="0 0 0" />
    <parent
      link="RL_hip" />
    <child
      link="RL_thigh" />
    <axis
      xyz="0 1 0" />
    <limit
      lower="-0.5236"
      upper="4.5379"
      effort="23.7"
      velocity="30.1" />
  </joint>
  <link
    name="RL_calf">
    <inertial>
      <origin
        xyz="0.00548 -0.000975 -0.115"
        rpy="0 0 0" />
      <mass
        value="0.154" />
      <inertia
        ixx="0.00108"
        ixy="3.4E-07"
        ixz="1.72E-05"
        iyy="0.0011"
        iyz="8.28E-06"
        izz="3.29E-05" />
    </inertial>
    <visual>
      <origin
        xyz="0 0 0"
        rpy="0 0 0" />
      <geometry>
        <mesh
          filename="../dae/calf.dae" />
      </geometry>
      <material
        name="">
        <color
          rgba="1 1 1 1" />
      </material>
    </visual>
    <collision>
      <origin rpy="0 -0.2 0" xyz="0.01 0 -0.06" />
      <geometry>
        <cylinder length="0.12" radius="0.013" />
      </geometry>
    </collision>
  </link>
  <joint
    name="RL_calf_joint"
    type="revolute">
    <origin
      xyz="0 0 -0.213"
      rpy="0 0 0" />
    <parent
      link="RL_thigh" />
    <child
      link="RL_calf" />
    <axis
      xyz="0 1 0" />
    <limit
      lower="-2.7227"
      upper="-0.83776"
      effort="35.55"
      velocity="20.07" />
  </joint>
  <link
    name="RL_calflower">
    <collision>
      <origin rpy="0 0 0" xyz="0 0 0" />
      <geometry>
        <cylinder length="0.065" radius="0.011" />
      </geometry>
    </collision>
  </link>
  <joint
    name="RL_calflower_joint"
    type="fixed">
    <origin
      xyz="0.020 0 -0.148"
      rpy="0 0.05 0" />
    <parent
      link="RL_calf" />
    <child
      link="RL_calflower" />
    <axis
      xyz="0 0 0" />
  </joint>
  <link
    name="RL_calflower1">
    <collision>
      <origin rpy="0 0 0" xyz="0 0 0" />
      <geometry>
        <cylinder length="0.03" radius="0.0155" />
      </geometry>
    </collision>
  </link>
  <joint
    name="RL_calflower1_joint"
    type="fixed">
    <origin
      xyz="-0.01 0 -0.04"
      rpy="0 0.48 0" />
    <parent
      link="RL_calflower" />
    <child
      link="RL_calflower1" />
    <axis
      xyz="0 0 0" />
  </joint>
  <link
    name="RL_foot">
    <inertial>
      <origin
        xyz="0 0 0"
        rpy="0 0 0" />
      <mass
        value="0.04" />
      <inertia
        ixx="9.6e-06"
        ixy="0"
        ixz="0"
        iyy="9.6e-06"
        iyz="0"
        izz="9.6e-06" />
    </inertial>
    <visual>
      <origin
        xyz="0 0 0"
        rpy="0 0 0" />
      <geometry>
        <mesh
          filename="../dae/foot.dae" />
      </geometry>
      <material
        name="">
        <color
          rgba="1 1 1 1" />
      </material>
    </visual>
    <collision>
      <origin rpy="0 0 0" xyz="-0.002 0 0" />
      <geometry>
        <sphere radius="0.022" />
      </geometry>
    </collision>
  </link>
  <joint
    name="RL_foot_joint"
    type="fixed" dont_collapse="true">
    <origin
      xyz="0 0 -0.213"
      rpy="0 0 0" />
    <parent
      link="RL_calf" />
    <child
      link="RL_foot" />
    <axis
      xyz="0 0 0" />
  </joint>
  <link
    name="RR_hip">
    <inertial>
      <origin
        xyz="0.0054 -0.00194 -0.000105"
        rpy="0 0 0" />
      <mass
        value="0.678" />
      <inertia
        ixx="0.00048"
        ixy="-3.01E-06"
        ixz="-1.11E-06"
        iyy="0.000884"
        iyz="1.42E-06"
        izz="0.000596" />
    </inertial>
    <visual>
      <origin
        xyz="0 0 0"
        rpy="3.1415 3.1415 0" />
      <geometry>
        <mesh
          filename="../dae/hip.dae" />
      </geometry>
      <material
        name="">
        <color
          rgba="1 1 1 1" />
      </material>
    </visual>
    <collision>
      <origin rpy="0 0 0" xyz="0 -0.08 0" />
      <geometry>
        <box size="0.09 0.067 0.09" />
      </geometry>
    </collision>
  </link>
  <joint
    name="RR_hip_joint"
    type="revolute">
    <origin
      xyz="-0.1934 -0.0465 0"
      rpy="0 0 0" />
    <parent
      link="base" />
    <child
      link="RR_hip" />
    <axis
      xyz="1 0 0" />
    <limit
      lower="-1.0472"
      upper="1.0472"
      effort="23.7"
      velocity="30.1" />
  </joint>
  <link
    name="RR_thigh">
    <inertial>
      <origin
        xyz="-0.00374 0.0223 -0.0327"
        rpy="0 0 0" />
      <mass
        value="1.152" />
      <inertia
        ixx="0.00584"
        ixy="-8.72E-05"
        ixz="-0.000289"
        iyy="0.0058"
        iyz="-0.000808"
        izz="0.00103" />
    </inertial>
    <visual>
      <origin
        xyz="0 0 0"
        rpy="0 0 0" />
      <geometry>
        <mesh
          filename="../dae/thigh_mirror.dae" />
      </geometry>
      <material
        name="">
        <color
          rgba="1 1 1 1" />
      </material>
    </visual>
    <collision>
      <origin rpy="0 1.5707963267948966 0" xyz="0 0 -0.1065" />
      <geometry>
        <box size="0.11 0.0245 0.034" />
      </geometry>
    </collision>
  </link>
  <joint
    name="RR_thigh_joint"
    type="revolute">
    <origin
      xyz="0 -0.0955 0"
      rpy="0 0 0" />
    <parent
      link="RR_hip" />
    <child
      link="RR_thigh" />
    <axis
      xyz="0 1 0" />
    <limit
      lower="-0.5236"
      upper="4.5379"
      effort="23.7"
      velocity="30.1" />
  </joint>
  <link
    name="RR_calf">
    <inertial>
      <origin
        xyz="0.00548 0.000975 -0.115"
        rpy="0 0 0" />
      <mass
        value="0.154" />
      <inertia
        ixx="0.00108"
        ixy="-3.4E-07"
        ixz="1.72E-05"
        iyy="0.0011"
        iyz="-8.28E-06"
        izz="3.29E-05" />
    </inertial>
    <visual>
      <origin
        xyz="0 0 0"
        rpy="0 0 0" />
      <geometry>
        <mesh
          filename="../dae/calf_mirror.dae" />
      </geometry>
      <material
        name="">
        <color
          rgba="1 1 1 1" />
      </material>
    </visual>
    <collision>
      <origin rpy="0 -0.2 0" xyz="0.01 0 -0.06" />
      <geometry>
        <cylinder length="0.12" radius="0.013" />
      </geometry>
    </collision>
  </link>
  <joint
    name="RR_calf_joint"
    type="revolute">
    <origin
      xyz="0 0 -0.213"
      rpy="0 0 0" />
    <parent
      link="RR_thigh" />
    <child
      link="RR_calf" />
    <axis
      xyz="0 1 0" />
    <limit
      lower="-2.7227"
      upper="-0.83776"
      effort="35.55"
      velocity="20.07" />
  </joint>
  <link
    name="RR_calflower">
    <collision>
      <origin rpy="0 0 0" xyz="0 0 0" />
      <geometry>
        <cylinder length="0.065" radius="0.011" />
      </geometry>
    </collision>
  </link>
  <joint
    name="RR_calflower_joint"
    type="fixed">
    <origin
      xyz="0.020 0 -0.148"
      rpy="0 0.05 0" />
    <parent
      link="RR_calf" />
    <child
      link="RR_calflower" />
    <axis
      xyz="0 0 0" />
  </joint>
  <link
    name="RR_calflower1">
    <collision>
      <origin rpy="0 0 0" xyz="0 0 0" />
      <geometry>
        <cylinder length="0.03" radius="0.0155" />
      </geometry>
    </collision>
  </link>
  <joint
    name="RR_calflower1_joint"
    type="fixed">
    <origin
      xyz="-0.01 0 -0.04"
      rpy="0 0.48 0" />
    <parent
      link="RR_calflower" />
    <child
      link="RR_calflower1" />
    <axis
      xyz="0 0 0" />
  </joint>
  <link
    name="RR_foot">
    <inertial>
      <origin
        xyz="0 0 0"
        rpy="0 0 0" />
      <mass
        value="0.04" />
      <inertia
        ixx="9.6e-06"
        ixy="0"
        ixz="0"
        iyy="9.6e-06"
        iyz="0"
        izz="9.6e-06" />
    </inertial>
    <visual>
      <origin
        xyz="0 0 0"
        rpy="0 0 0" />
      <geometry>
        <mesh
          filename="../dae/foot.dae" />
      </geometry>
      <material
        name="">
        <color
          rgba="1 1 1 1" />
      </material>
    </visual>
    <collision>
      <origin rpy="0 0 0" xyz="-0.002 0 0" />
      <geometry>
        <sphere radius="0.022" />
      </geometry>
    </collision>
  </link>
  <joint
    name="RR_foot_joint"
    type="fixed" dont_collapse="true">
    <origin
      xyz="0 0 -0.213"
      rpy="0 0 0" />
    <parent
      link="RR_calf" />
    <child
      link="RR_foot" />
    <axis
      xyz="0 0 0" />
  </joint>
  <link
    name="imu">
    <inertial>
      <origin
        xyz="0 0 0"
        rpy="0 0 0" />
      <mass
        value="0" />
      <inertia
        ixx="0"
        ixy="0"
        ixz="0"
        iyy="0"
        iyz="0"
        izz="0" />
    </inertial>
  </link>
  <joint
    name="imu_joint"
    type="fixed">
    <origin
      xyz="-0.02557 0 0.04232"
      rpy="0 0 0" />
    <parent
      link="base" />
    <child
      link="imu" />
    <axis
      xyz="0 0 0" />
  </joint>
  <link
    name="radar">
    <inertial>
      <origin
        xyz="0 0 0"
        rpy="0 0 0" />
      <mass
        value="0" />
      <inertia
        ixx="0"
        ixy="0"
        ixz="0"
        iyy="0"
        iyz="0"
        izz="0" />
    </inertial>
  </link>
  <joint
    name="radar_joint"
    type="fixed">
    <origin
      xyz="0.28945 0 -0.046825"
      rpy="0 2.8782 0" />
    <parent
      link="base" />
    <child
      link="radar" />
    <axis
      xyz="0 0 0" />
  </joint>
  <link name="camera_box">
    <visual>
      <origin rpy="0 0.349 0" xyz="0.343 0 0.070"/>
      <geometry>
        <box size="0.025 0.09 0.025"/>
      </geometry>
      <material name="red"/>
    </visual>
  </link>
  <joint name="fixed_camera_box" type="fixed">
    <origin rpy="0 0 0" xyz="0 0 0"/>
    <parent link="base"/>
    <child link="camera_box"/>
  </joint>
  <link
    name="base_link">
    <inertial>
      <origin
        xyz="0.0031704 2.7625E-05 0.024929"
        rpy="0 0 0" />
      <mass
        value="0.16674" />
      <inertia
        ixx="0.00014155"
        ixy="2.1973E-07"
        ixz="1.3903E-06"
        iyy="0.00015179"
        iyz="5.1428E-08"
        izz="0.00027875" />
    </inertial>
    <visual>
      <origin
        xyz="0 0 0"
        rpy="0 0 0" />
      <geometry>
        <mesh
          filename="../dae/base_link.STL" />
      </geometry>
      <material
        name="">
        <color
          rgba="1 1 1 1" />
      </material>
    </visual>
    <collision>
      <origin
        xyz="0 0 0"
        rpy="0 0 0" />
      <geometry>
        <mesh
          filename="../dae/base_link.STL" />
      </geometry>
    </collision>
  </link>
  <joint name="arm_base" type="fixed">
    <origin rpy="0 0 0" xyz="0 0 0"/>
    <parent link="base"/>
    <child link="base_link"/>
  </joint>
  <link
    name="Link1">
    <inertial>
      <origin
        xyz="-0.0019964 -0.00011691 0.027447"
        rpy="0 0 0" />
      <mass
        value="0.16166" />
      <inertia
        ixx="8.6547E-05"
        ixy="-5.5665E-08"
        ixz="-1.2705E-07"
        iyy="7.3583E-05"
        iyz="3.5719E-07"
        izz="8.2287E-05" />
    </inertial>
    <visual>
      <origin
        xyz="0 0 0"
        rpy="0 0 0" />
      <geometry>
        <mesh
          filename="../dae/Link1.STL" />
      </geometry>
      <material
        name="">
        <color
          rgba="1 1 1 1" />
      </material>
    </visual>
    <collision>
      <origin
        xyz="0 0 0"
        rpy="0 0 0" />
      <geometry>
        <mesh
          filename="../dae/Link1.STL" />
      </geometry>
    </collision>
  </link>
  <joint
    name="joint1"
    type="fixed">
    <origin
      xyz="-2.5E-05 0 0.0508"
      rpy="0 0 0" />
    <parent
      link="base_link" />
    <child
      link="Link1" />
    <axis
      xyz="0 0 1" />
    <limit
      lower="-2.35"
      upper="2.35"
      effort="0"
      velocity="0" />
  </joint>
  <link
    name="Link2">
    <inertial>
      <origin
        xyz="0.0002018 0.19201 -0.027407"
        rpy="0 0 0" />
      <mass
        value="0.20213" />
      <inertia
        ixx="0.00025682"
        ixy="-1.139E-07"
        ixz="5.5666E-08"
        iyy="6.3307E-05"
        iyz="-3.5717E-07"
        izz="0.00022968" />
    </inertial>
    <visual>
      <origin
        xyz="0 0 0"
        rpy="0 0 0" />
      <geometry>
        <mesh
          filename="../dae/Link2.STL" />
      </geometry>
      <material
        name="">
        <color
          rgba="1 1 1 1" />
      </material>
    </visual>
    <collision>
      <origin
        xyz="0 0 0"
        rpy="0 0 0" />
      <geometry>
        <mesh
          filename="../dae/Link2.STL" />
      </geometry>
    </collision>
  </link>
  <joint
    name="joint2"
    type="fixed">
    <origin
      xyz="0 -0.028 0.0588"
      rpy="1.5708 0 0" />
    <parent
      link="Link1" />
    <child
      link="Link2" />
    <axis
      xyz="0 0 -1" />
    <limit
      lower="-1.57"
      upper="1.57"
      effort="0"
      velocity="0" />
  </joint>
  <link
    name="Link3">
    <inertial>
      <origin
        xyz="0.016339 0.044495 -0.0275"
        rpy="0 0 0" />
      <mass
        value="0.064818" />
      <inertia
        ixx="1.7393E-05"
        ixy="-2.6967E-06"
        ixz="6.6442E-12"
        iyy="1.2688E-05"
        iyz="1.2785E-12"
        izz="1.5042E-05" />
    </inertial>
    <visual>
      <origin
        xyz="0 0 0"
        rpy="0 0 0" />
      <geometry>
        <mesh
          filename="../dae/Link3.STL" />
      </geometry>
      <material
        name="">
        <color
          rgba="1 1 1 1" />
      </material>
    </visual>
    <collision>
      <origin
        xyz="0 0 0"
        rpy="0 0 0" />
      <geometry>
        <mesh
          filename="../dae/Link3.STL" />
      </geometry>
    </collision>
  </link>
  <joint
    name="joint3"
    type="fixed">
    <origin
      xyz="0 0.2693 0.0005"
      rpy="0 0 0" />
    <parent
      link="Link2" />
    <child
      link="Link3" />
    <axis
      xyz="0 0 -1" />
    <limit
      lower="-1.57"
      upper="1.57"
      effort="0"
      velocity="0" />
  </joint>
  <link
    name="Link4">
    <inertial>
      <origin
        xyz="-0.00015656 0.00028734 0.11148"
        rpy="0 0 0" />
      <mass
        value="0.085716" />
      <inertia
        ixx="3.4566E-05"
        ixy="-1.0126E-08"
        ixz="-1.6915E-09"
        iyy="3.9496E-05"
        iyz="9.4317E-08"
        izz="1.167E-05" />
    </inertial>
    <visual>
      <origin
        xyz="0 0 0"
        rpy="0 0 0" />
      <geometry>
        <mesh
          filename="../dae/Link4.STL" />
      </geometry>
      <material
        name="">
        <color
          rgba="1 1 1 1" />
      </material>
    </visual>
    <collision>
      <origin
        xyz="0 0 0"
        rpy="0 0 0" />
      <geometry>
        <mesh
          filename="../dae/Link4.STL" />
      </geometry>
    </collision>
  </link>
  <joint
    name="joint4"
    type="fixed">
    <origin
      xyz="0.0348 0.041975 -0.0275"
      rpy="0 1.5708 0" />
    <parent
      link="Link3" />
    <child
      link="Link4" />
    <axis
      xyz="0 0 1" />
    <limit
      lower="-2.35"
      upper="2.35"
      effort="0"
      velocity="0" />
  </joint>
  <link
    name="Link5">
    <inertial>
      <origin
        xyz="0.041939 0.0059823 -0.0238"
        rpy="0 0 0" />
      <mass
        value="0.055735" />
      <inertia
        ixx="1.3233E-05"
        ixy="-3.9361E-07"
        ixz="5.3016E-10"
        iyy="8.7135E-06"
        iyz="4.9547E-10"
        izz="1.1127E-05" />
    </inertial>
    <visual>
      <origin
        xyz="0 0 0"
        rpy="0 0 0" />
      <geometry>
        <mesh
          filename="../dae/Link5.STL" />
      </geometry>
      <material
        name="">
        <color
          rgba="1 1 1 1" />
      </material>
    </visual>
    <collision>
      <origin
        xyz="0 0 0"
        rpy="0 0 0" />
      <geometry>
        <mesh
          filename="../dae/Link5.STL" />
      </geometry>
    </collision>
  </link>
  <joint
    name="joint5"
    type="fixed">
    <origin
      xyz="-0.0237 0.0001 0.16318"
      rpy="0 -1.5708 0" />
    <parent
      link="Link4" />
    <child
      link="Link5" />
    <axis
      xyz="0 0 -1" />
    <limit
      lower="-1.57"
      upper="1.57"
      effort="0"
      velocity="0" />
  </joint>
  <link
    name="Link6">
    <inertial>
      <origin
        xyz="7.7813E-06 0.004578 0.075476"
        rpy="0 0 0" />
      <mass
        value="0.1117" />
      <inertia
        ixx="2.306E-05"
        ixy="-4.8965E-08"
        ixz="-5.4444E-10"
        iyy="4.2359E-05"
        iyz="1.8404E-07"
        izz="5.1477E-05" />
    </inertial>
    <visual>
      <origin
        xyz="0 0 0"
        rpy="0 0 0" />
      <geometry>
        <mesh
          filename="../dae/Link6.STL" />
      </geometry>
      <material
        name="">
        <color
          rgba="1 1 1 1" />
      </material>
    </visual>
    <collision>
      <origin
        xyz="0 0 0"
        rpy="0 0 0" />
      <geometry>
        <mesh
          filename="../dae/Link6.STL" />
      </geometry>
    </collision>
  </link>
  <joint
    name="joint6"
    type="fixed">
    <origin
      xyz="0.0596 -0.001075 -0.0238"
      rpy="0 1.5708 0" />
    <parent
      link="Link5" />
    <child
      link="Link6" />
    <axis
      xyz="0 0 -1" />
    <limit
      lower="-2.35"
      upper="2.35"
      effort="0"
      velocity="0" />
  </joint>
</robot>